Workbook

Sheet Sep-18
A1: Name : Rahul
A2: Phone : 9209141067
A3: Name : Vikram singh
A4: Phone : 6005702812
A5: Name : Lool bail
A6: Phone : 7896645431

Sheet 19.09.24
A1: CLIENT | B1: REMARK
A2: Name : brg
A3: Phone : 9696969961 | B3: cb
A4: Name : ARUN PANDURANG Lahamge
A5: Name : Ashu gupta ji Phone : 9215441441 | B5: ni
A6: Name : Babu
A7: Name : Chandan Pradhan Phone : 9556002317
A8: Name : Darshan
A9: Name : Debanjan Chakraborty
A10: Name : Dhairya Agarwal
A11: Name : ganapathi
A12: Name : Gautam Barman
A13: Name : Harsh Agarwal Phone : 9110112574 | B13: cd
A14: Name : hsndnke Phone : 9977657766 | B14: off
A15: Name : Jeevan Chavhan | B15: ni
A16: Name : Jignesh Mhapralkar Phone : 9372207414 | B16: cd
A17: Name : Kk Phone : 7777777777 | B17: invalid
A18: Name : MOHAMMAD HAFIZ MANIHAR Phone : 9175007475 | B18: INTERESRED | C18: MAHENDRA
A19: Name : Neeru Phone : 9650709814 | B19: INTRUSTED
A20: Name : Piyush sharma Phone : 7982613924 | B20: npc
A21: Name : Pratik
A22: Name : Pruthibiraj Patel Phone : 8658640336
A23: Name : Raghavendra Phone : 9886630662 | B23: npc
A24: Name : Rishi Phone : 8828737975 | B24: busy
A25: Name : Ritishi kaul Phone : 8899775847 | B25: off
A26: Name : Rohit Phone : 8898800696 | B26: off
A27: Name : Rupali Phone : 9870339945 | B27: CB
A28: Name : Saibal Ghosh
A29: Name : Santha
A30: Name : Santhosh
A31: Name : Saraswathy MR
A32: Name : Saraswathy MR Phone : 9449275034 | B32: ni
A33: Name : Sathish Phone : 8838202699 | B33: followup
A34: Name : Shanmukha
A35: Name : Srinath S Phone : 8050549720 | B35: FT | C35: amit
A36: Name : SUMANGAL BISWAS Phone : 7076502262 | B36: INTRUSTED
A37: Name : Swaraj
A38: Name : Tanmoy
A39: Name : Tanmoy Phone : 9641107291
A40: Name : Tejal Pujari Phone : 9372697443 | B40: npc
...

Sheet 20.09.24
A1: Name : Ajit
A2: Phone : 8412059100 | B2: cb
A3: Name : Shahraaz Phone : 9076378461 | B3: low
A4: Name : Biplab shill Phone : 8402015072 | B4: cb
A5: Name : Nalini Phone : 9750581992 | B5: npc
A6: Name : Priyanjana Saha Phone : 6291034461 | B6: ni
A7: Name : Razak Phone : 9746447138 | B7: cd
A8: Name : Shalu Balan Phone : 9326548305 | B8: cd
A9: Name : Vimal Phone : 9841162338 | B9: npc
A10: Name : Anil kumar Pradhan Phone : 8093477991 | B10: ofs
A11: Name : Selva Phone : 7892484905 | B11: off
A12: Name : Rasheswari meher Phone : 6370524859 | B12: ni
A13: Name : Sajid Phone : 8447292344 | B13: npc
A14: Name : Rekha Das Phone : 7576813140 | B14: ni
A15: Name : Pradeep ku behari Phone : 9437265483 | B15: FT | C15: NARMADA | F15: 27/12/2024
A16: Name : Sbw Phone : 7892104884 | B16: cd
A17: Name : Vijay Phone : 9944998783 | B17: npc
A18: Name : Mainul Islam Phone : 9864934575 | B18: cb
A19: Name : Sajal Biswas Phone : 8961323563 | B19: invalid
A20: Name : Rajkishorepandey Phone : 9131791220 | B20: off
A21: Name : ANUP CHATTERJEE Phone : 9749684372 | B21: npc
A22: Name : Raj Phone : 8561082963 | B22: off
A23: Name : Manohar mhaske Phone : 9011191477 | B23: followup
A24: Name : JITHIN K Phone : 8089957491 | B24: npc
A25: Name : DATTATRAY MATE Phone : 9130057340 | B25: busy
A26: Name : Shreenivas Phone : 7259870553 | B26: cd
A27: Name : abc
A28: Phone : 9876543210 | B28: busy
A29: Name : Sree avenash Phone : 7538824243 | B29: cd
A30: Name : Partha sarkar Phone : 9709031035 | B30: ni
A31: Name : Usha Phone : 9326189007 | B31: followup
A32: Name : Ajit Phone : 8412059100 | B32: no fund
A33: Name : Sanjeeb Mohanty
A34: Phone : 9323791057 | B34: NI
A35: Name : ANEESH
A36: Phone : 9947775292 | B36: npc
A37: Name : Raju
A38: Phone : 9494956056 | B38: old client
A39: Name : Sumit
A40: Phone : 9163420355 | B40: intrusted
...

Sheet 21.09.24
A1: Name : Karanveer thapa
A2: Phone : 9717871816 | B2: NI
A3: Name : Bheem singh Phone : 7503012006 | B3: NI
A4: Name : MOJIBUR RAHMAN Phone : 9064745645 | B4: BUSY
A5: Name : Sujit Phone : 9937148555 | B5: CB
A6: Name : Vasu Phone : 9787593672 | B6: FT
A7: Name : Rafeeque Phone : 9846789594 | B7: BUSY
A8: Name : Atiisha dev Phone : 9789645727 | B8: CD
A9: Name : Parvez Khan Phone : 9922424526 | B9: NI
A10: Name : Sandesh MK Phone : 9747910441 | B10: OFS
A11: Name : SIVANNA G Phone : 9449615340 | B11: FT
A12: Name : Madhu Phone : 9860767804 | B12: NI
A13: Name : Naveen Sharma Phone : 9811728340 | B13: BUSY
A14: Name : Bas Phone : 9940489606 | B14: CD
A15: Name : Rohit Sheikh Phone : 9775259483 | B15: NI | D15: SS
A16: Name : Abhishek Phone : 8087460075 | B16: NI
A17: Name : Onkar Phone : 8485858190 | B17: CD
A18: Name : Suraj Phone : 9846665011 | B18: FT | C18: AMIT
A19: Name : shivaprasad s k Phone : 7892144731
A20: Name : AYUSH Phone : 8527232077 | B20: INTRUSTED | G20: intrusted
A21: Name : ARIJITROY Phone : 8001604222 | B21: CB
A22: Name : Jj Phone : 9637140238 | B22: NPC | C22: **********
A23: Name : Pankaj karmakar Phone : 8789302722 | B23: INTRUSTED
A24: Name : Pramod Somkuwar Phone : 9764717880 | B24: NPC
A25: Name : Sunny Phone : 9958863906 | B25: NPC
A26: Name : Rahul Phone : 8766206998 | B26: FT
A27: Name : A Banerjee Phone : 9748617554 | B27: INTRUSTED
A28: Name : Harish Kumar Bhola Phone : 8076484162 | B28: NPC
A29: Name : VIDHI GALA Phone : 8779293324 | B29: NPC
A30: Name : Kavya
A31: Phone : 7028832966 | B31: NI | C31: *******
A32: Name : Phool kumar
A33: Phone : 8882635904 | B33: INTRUSTED
A34: Name : Aashiya
A35: Phone : 9022044154 | B35: CB | C35: MAHENDRA
A36: Name : Ashis Kumar hazra
A37: Phone : 9434433452 | B37: CD
A38: Name : Somnath Ghosal
A39: Phone : 9748281010
A40: Name : Shweta Phone : 9999472738 | B40: NPC
...

Sheet 22.23.09.24
A1: Name : Hemraj
A2: Phone : 8939259332 | B2: NI
A3: Name : Rahul kumbalkar Phone : 7587794750 | B3: NI
A4: Name : Nba Phone : 8638656375 | B4: NPC
A5: Name : SHIBAM HALDER Phone : 8967116407 | B5: NI
A6: Name : Balaram kar Phone : 8900245786 | B6: INVALID
A7: Name : saroj bhagat Phone : 8806944827 | B7: FRESHER
A8: Name : Ninjh Phone : 9884694477 | B8: NI
A9: Name : RAJENDRA AMBORE Phone : 9730652223 | B9: FT
A10: Name : Rahul Patil Phone : 9975536165 | B10: BUSY
A11: Name : Niranjan Bhowmick Phone : 9038471201 | B11: NPC
A12: Name : Kabirul Phone : 9836132501 | B12: NI
A13: Name : Mohandas Phone : 9535948486 | B13: NPC
... A17: Name : Nikhil shah Phone : 8779675103 | B17: NI
A18: Name : Rahul Lende
A19: Phone : 7709453093 | B19: BUSY
A20: Name : ASHOK KUMAR K N
A21: Phone : 8073056665 | B21: CD
A22: Name : Ramaraju Manthina Phone : 9533807776 | B22: NI
A23: Name : Vijayakumar SR Phone : 9741066256 | B23: NPC
A24: Name : Chandan N U Phone : 9019770641 | B24: NPC
A25: Name : N C Barman Phone : 7908058591 | B25: FT
A26: Name : Manjunath Phone : 9986191317 | B26: NI
A27: Name : Lakshman Dhakarge Phone : 9325579327 | B27: FT
A28: Name : Dibyajyoti Dash Phone : 9583636025 | B28: CB
A29: Name : Saheb sk Phone : 8617892442 | B29: FT
A30: Name : DARAMKISHORE Phone : 9493248748 | B30: FT
A31: Name : Dk Phone : 8102270029 | B31: WRONG
A32: Name : Lokesh Phone : 9398548345 | B32: NPC
... A34: Name : Vijayakumar SR Phone : 9876543210 | B34: BUSY
A35: Name : Kuppi
A36: Phone : 8277672562
A37: Name : Subhankar Bhowmik Phone : 9046388879 | B37: NPC
A38: Name : Mallesha TG Phone : 9019555736 | B38: FT
A39: Name : Rohit Paradhe
A40: Phone : 9324986602 | B40: FT ALGO
A41: Name : Balu Phone : 6300342742 | B41: NPC
A42: Name : Samir Phone : 8812006695 | B42: NPC
A43: Name : Kuppi Phone : 8277672562 | B43: NPC
A44: Name : Khalid
...

Sheet 24.09.24
A1: name | B1: remark | C1: EMP.
A2: Name : Aravindh S | B2: 0
A3: Phone : 9566662953 | B3: CB
A4: Name : Suvendu Kamila Phone : 8910626514 | B4: INTRUSTED | C4: pawan
A5: Name : Dibyendu Phone : 9051904454 | B5: low investment | C5: amit
A6: Name : Hardik Phone : 8851660633 | B6: 0
A7: Name : Kapish Phone : 9832638201 | B7: call back
A8: Name : Rishi Aneja Phone : 9654332370 | B8: Follow up
A9: Name : T Phone : 9888532644 | B9: NPC
A10: Name : Ramesh Madiwalar Phone : 8217490542 | B10: SWITCH OF
A11: Name : Prasad Khartude Phone : 9960606789 | B11: CALL CUT
A12: Name : Khushal pawar Phone : 8169561139 | B12: CB
A13: Name : Sure.Subbarao Phone : 8008879504 | B13: 0
A14: Name : Venkat Phone : 9942691093 | B14: CB | C14: VIKASH
A15: Name : Rajan Phone : 9004478262 | B15: 0
A16: Name : Vishal Eknath Shivatare Phone : 9923245833 | B16: CB
A17: Name : Yaseen Phone : 9032712106 | B17: IN
A18: Name : Dipak sarkar Phone : 9832575982 | B18: low investment
A19: Name : Preeti Phone : 9342939266 | B19: NPC
A20: Name : SIVAKUMAR Phone : 9940710203 | B20: FT
A21: Name : NIHAL MANISH DEVKAR Phone : 8850694190 | B21: NI
A22: Name : Jony MD Phone : 7377327811 | B22: FT | C22: Rishi
A23: Name : Umar Khan Phone : 9073846362 | B23: LI | C23: ABHAY
A24: Name : Iyyappan Phone : 9751559220 | B24: NPC
A25: Name : Kakali Bagui Phone : 9836160994 | B25: NPC
A26: Name : Mahesh suryawanshi Phone : 9689363869 | B26: CB
A27: Name : Renu Kumari Phone : 8826255121 | B27: NPC
A28: Name : Nikita Dahiya Phone : 9468315098 | B28: NI
A29: Name : Puneet Jaiswal Phone : 9540801630 | B29: NI
A30: Name : Krishna Phone : 8639947116 | B30: NPC
A31: Name : prashant thakur Phone : 8084212902 | B31: CB
A32: Name : Mohammed Phone : 8082130587 | B32: CB
A33: Name : Raja Phone : 8658895558 | B33: FT | C33: AMIT
A34: Name : Sainath ramchandra chewale | B34: 0
A35: Phone : 9403249278 | B35: CB
A36: Name : Mahabir Phone : 9625034471 | B36: Fund issue
A37: Name : Jony MD Phone : 7377327811 | B37: FT | C37: Rishi
A38: Name : bhaskar Phone : 7385405149 | B38: AAJ HI PAYMENT DALA HAI
A39: Name : Suvankar pal | B39: 0
A40: Phone : 7432864522 | B40: Cd wc
...

Sheet Sheet4
A1: TOTAL LEADS -98 | F1: TOTAL LEADS - 160
A2: Date -23.09.24 | F2: Date -24.09.24
A3: FT | B3: 15 | F3: FT | G3: 16
A4: INTERESTED | B4: 2 | F4: INTERESTED | G4: 13
A5: FOLLOWUP | B5: 1 | F5: FOLLOWUP | G5: 4
A6: CB | B6: 5 | F6: CB | G6: 19
A7: BUSY | B7: 5 | F7: BUSY | G7: 14
A8: NPC | B8: 23 | F8: NPC | G8: 31
A9: NI | B9: 14 | F9: NI | G9: 20
A10: OTHERS | B10: 33 | F10: OTHERS | G10: 43
A11: EOD - | F11: EOD -

Sheet Sheet3
A1: TOTAL LEADS - 135 | F1: TOTAL LEADS - 141
A2: Date -25.09.24 | F2: Date -26.09.24
A3: FT | B3: =COUNTIFS('25-09-2024'!$D:$D,Sheet3!A3) -> 13 | F3: FT | G3: 9
A4: INTERESTED | B4: =COUNTIFS('25-09-2024'!$D:$D,Sheet3!A4) -> 8 | F4: INTERESTED | G4: 18
A5: FOLLOWUP | B5: 4 | F5: FOLLOWUP | G5: 4
A6: CB | B6: 22 | F6: CB | G6: 10
A7: BUSY | B7: =COUNTIFS('25-09-2024'!$D:$D,Sheet3!A7) -> 17 | F7: BUSY | G7: 20
A8: NPC | B8: 22 | F8: NPC | G8: 34
A9: NI | B9: =COUNTIFS('25-09-2024'!$D:$D,Sheet3!A9) -> 15 | F9: NI | G9: 28
A10: OTHERS | B10: 36 | F10: OTHERS | G10: 18

Sheet 25-09-2024
A1: clint NO. | B1: Name | C1: mobile NO. | D1: Remark | E1: emp. Name
A2: 1 | B2: Glenn | C2: 9820551983 | D2: FT | E2: KAMINI
A3: 2 | B3: MUNEESWARAN G | C3: 8144764304 | D3: FT | E3: KAMINI
A4: 3 | B4: Rahman ansari | C4: 9158594883 | D4: FT | E4: SHRUTI
A5: 4 | B5: Aaaa | C5: 9876543210 | D5: BUSY
A6: 5 | B6: Akshay Choudhar | C6: 7798275453 | D6: CB | E6: PREETI
A7: 6 | B7: Shrishail Kattimani | C7: 8999304796 | D7: NI
A8: 7 | B8: Sabitha | C8: 7306671155 | D8: BUSY
A9: 8 | B9: Tanmay | C9: 9172397171 | D9: FT 12K | E9: AMIT
A10: 9 | B10: Mo u bhiya | C10: 9373504866 | D10: SWITCH OFF
A11: 10 | B11: George K S | C11: 9447480030 | D11: FT | E11: KAMINI
A12: 11 | B12: Manikeshwar | C12: 8340796049 | D12: FT | E12: RISHI
A13: 12 | B13: Venkatappa | C13: 7892575720 | D13: SWITCH OFF
A14: 13 | B14: PAINX_UCHIHA | C14: 7439864710 | D14: FT | E14: AMIT
A15: 14 | B15: Sabena chalke | C15: 9322043326 | D15: CB | E15: MAHENDRA
A16: 15 | B16: Tushar Mandlik | C16: 7757913828 | D16: CB | E16: VOM
A17: 16 | B17: Bablu Dutta | C17: 7984427768 | D17: CB | E17: SHRUTI
A18: 17 | B18: Charles | C18: 8754797783 | D18: NI
A19: 18 | B19: Asif | C19: 9846360014 | D19: INTERESTED | E19: VRADDHI
A20: 19 | B20: Dheeraj R | C20: 8296790961 | D20: LANG. ISSUE
A21: 20 | B21: ARIVUSELVAM | C21: 9843701854 | D21: NI
A22: 21 | B22: Sukanta KUNDU | C22: 9073696055 | D22: CB | E22: AMIT
A23: 23 | B23: no name | C23: 9740101295 | D23: NPC
A24: 24 | B24: RAMESH yadav | C24: 8104536093 | D24: NPC
A25: 25 | B25: Sukhbir Singh | C25: 9953142956 | D25: NC
A26: 26 | B26: Saikat Mondal | C26: 9035251429 | D26: NPC
A27: 27 | B27: Ramesh | C27: 7373710124 | D27: NI
A28: 28 | B28: Atish palmal | C28: 8609420432 | D28: CB | E28: SHRUTI
A29: 29 | B29: KARTHIKA N P | C29: 7483675446 | D29: CB | E29: VOM
A30: 30 | B30: Soujanya mullick | C30: 8336044808 | D30: INTERESTED | E30: PAWAN
A31: 31 | B31: Anuraj | C31: 9744178130 | D31: SWITCH OFF
A32: 33 | B32: Ayyappa | C32: 9538250146 | D32: NI
A33: 34 | B33: Nagaraj | C33: 9964004771 | D33: FOLLOW UP | E33: POONAM
A34: 35 | B34: AYUSMAN KUMAR PATNAIK | C34: 6303124562 | D34: CB | E34: KAMINI
A35: 36 | B35: Priya | C35: 9742123085 | D35: INTERESTED | E35: PREETI
A36: 37 | B36: Arindam Tarafdar | C36: 9477223561 | D36: NPC
A37: 38 | B37: Satyapriya Mohapatra | C37: 7750995177 | D37: NI
A38: 39 | B38: sanu biswas | C38: 9800345683 | D38: NI
A39: 40 | B39: Palash | C39: 8346989573 | D39: SWITCH OFF
A40: 41 | B40: Yash | C40: 9881226385 | D40: CB | E40: R C
...

Sheet 26-sep-2024
A1: clint details | B1: remark | C1: EMP. DETAILS
A2: NEW 26/SEP/2024
A3: Name : Samir Chakraborty
A4: Phone : 9433777122 | B4: FT | C4: KAMINI
A5: Name : Aaa
A6: Phone : 9789373829 | B6: NI | D6: FT AMIT
A7: Name : Ghogare Tanaji Phone : 7741978721 | B7: CB | C7: SUNITA
A8: Name : ashwin
A9: Phone : 9209199727 | B9: NI
A10: Name : Uv
A11: Phone : 8237484229 | B11: NPC
A12: Name : K P Kumar
A13: Phone : 9566074122 | B13: FT | C13: VOM
A14: Name : ANIL KUMAR
A15: Phone : 9874148118 | B15: INTERESTED | C15: RISHI
A16: Name : Arjuman Khan
A17: Phone : 8655355257 | B17: INTERESTED | C17: PREETI
A18: Name : Nikhil muttur
A19: Phone : 8073463354 | B19: BUSY
A20: Name : ajay
A21: Phone : 9887778877 | B21: WRONG NO.
A22: Name : Suresh
A23: Phone : 7019361155 | B23: FT | C23: AMIT
A24: NAME : NO
A25: Phone : 6238246567 | B25: NI
A26: Name : Utsav Kanji
A27: Phone : 8972542125 | B27: LOW CAPITAL | C27: RISHI
A28: Name : Samsher
A29: Phone : 7420006674 | B29: INTERESTED | C29: PREETI
A30: Name : ARVIND
A31: Phone : 7982557260 | B31: FOLLOW UP | C31: VOM
A32: Name : Tushar
A33: Phone : 7827522307 | B33: CB | C33: KAMINI
A34: Name : Mintu
A35: Phone : 8101560600 | B35: INTERESTED | C35: SUNITA
A36: Name : Md Muzammil Ahmed
A37: Phone : 8050899856 | B37: CB 6 PM | C37: VOM
A38: Mohd Nizamuddin Phone: 9738765021 | B38: INTERESTED | C38: AKSHAY
A39: Name : Karthik .p
A40: Phone : 8438983346 | B40: NPC
...

Sheet Sheet2
A1: TOTAL LEADS - 57 | G1: Dear:Amrit Phone: 9074341331 REQUEST Services: | H1: NPC
A2: Date -27.09.24 | G2: Dear:Raghvendra Phone: 7303013125 REQUEST Services: | H2: NI
A3: FT | B3: 9 | G3: Dear:Narayan Ray Phone: 7358205504 REQUEST Services: | H3: CB | I3: PAWAN
A4: INTERESTED | B4: 7 | G4: Dear:Suvra Sankar Bandyopadhyay Phone: 9038533484 REQUEST Services: | H4: CB | I4: SHRUTI
A5: FOLLOWUP | B5: 4 | G5: Dear:Bhavna Phone: 7499109277 REQUEST Services: | H5: NI
A6: CB | B6: 7 | G6: Dear:Arjun Phone: 7339012904 REQUEST Services: | H6: FOLLOW UP | I6: YASH
A7: BUSY | B7: 2 | G7: Dear:Karan jain Phone: 9899549999 REQUEST Services: | H7: NC
A8: NPC | B8: 9 | G8: Dear:Narendar singh Phone: 9079293791 REQUEST Services: | H8: NPC
A9: NI | B9: 4 | G9: Dear:Jithukrishna Phone: 6282241523 REQUEST Services: | H9: NPC
A10: OTHERS | B10: 15 | G10: Dear:Ravindra Phone: 9448141162 REQUEST Services: | H10: BUSY
G11: Dear:Prashant pimpale Phone: 9420608778 REQUEST Services: | H11: NPC
G12: Dear:prateep Phone: 9949110491 REQUEST Services: | H12: NC
G13: Dear:Gaurang Phone: 9537392139 REQUEST Services: | H13: BUSY
G14: Dear:Balasubramani Phone: 6383616335 REQUEST Services: | H14: NPC
G15: Dear:Shree Phone: 8087012263 REQUEST Services: | H15: NPC
G16: Dear:Aishwarya Manna Phone: 9875385905 REQUEST Services: | H16: BUSY
G17: Dear:Alok Sakpilly Phone: 9382645469 REQUEST Services: | H17: BUSY
G18: Dear:RUPESH Phone: 7972101977 REQUEST Services: | H18: BUSY
G19: Dear:narinder kumar Phone: 9168675387 REQUEST Services: | H19: NI
G20: Dear:Naveen Phone: 9015798639 REQUEST Services: | H20: NI
G21: Dear:Bhupal Sarkar Phone: 8638012490 REQUEST Services: | H21: NI
G22: Dear:SATYARAM DAS Phone: 7340930198 REQUEST Services: | H22: NC
... G24: Dear:Aravindraj Phone: 8098223310 REQUEST Services: | H24: LS
H25: NI
G26: Dear:abhishek Phone: 9768811896 REQUEST Services: | H26: NPC
G27: Dear:Pintu Saha Phone: 8145801299 REQUEST Services: | H27: NI
G28: Dear:GILLELLA Phone: 7013391182 REQUEST Services: | H28: NC
G29: Dear:Puskar santra Phone: 6290015054 REQUEST Services: | H29: NI
G30: Dear:Thyagaraj Phone: 9916301078 REQUEST Services: | H30: NPC
G31: Dear:Narendra nath gupta Phone: 7003252099 REQUEST Services: | H31: NPC
G32: Dear:Shaurabh Yadav Phone: 9560662261 REQUEST Services | H32: NO
G33: Dear:Vinod Phone: 8755983919 REQUEST Services: | H33: NPC
G34: Dear:Rty Phone: 6565768798 REQUEST Services: | H34: NC
G35: Dear:ATSIH MORE Phone: 8419993670 REQUEST Services: | H35: INTERESTED | I35: VRADDHI
G36: Dear:Almas Phone: 8617040360 REQUEST Services: | H36: CB | I36: PREETI
G37: Dear:Priyanka Gope Phone: 8257024657 REQUEST Services: | H37: FUND ISSUE
G38: Dear:R C jena Phone: 8249050234 REQUEST Services: | H38: NI
G39: Dear:jagdeep Phone: 9967534248 REQUEST Services: | H39: NPC
G40: Dear:somebody Phone: 1597534560 REQUEST Services: | H40: WRONG NO.
G41: Dear:Pooja Gadekar Phone: 9595150095 REQUEST Services: | H41: BUSY
...

Sheet 27-sep-2024
A1: Client details | B1: Remark | C1: Emp. Details
A2: Name : ERESH
A3: Phone : 8970168856 | B3: LS
A4: Name : Arunkumar Hk
A5: Phone : 9686712001 | B5: INTERESTED | C5: KAMINI
A6: Name : Theja
A7: Phone : 9381424331 | B7: FOLLOW UP | C7: AYUSH
A8: Name : Jjj
A9: Phone : 9357964214 | B9: SWITCH OFF
A10: Name : Mukul
A11: Phone : 9899932212 | B11: INTERESTED | C11: RISHI
A12: Name : Nidesh
A13: Phone : 8778593466 | B13: WRONG NO.
A14: ame : Praful Mahajan
A15: Phone : 7588553060 | B15: INTERESTED | C15: SUNITA
A16: Name : Fg
A17: Phone : 8307280274 | B17: CB | C17: KAMINI
A18: Name : David
A19: Phone : 8999999990 | B19: NPC
A20: Name : Sm
A21: Phone : 9340544720 | B21: FT | C21: SUNITA
A22: Name : Arunkumar Hk
A23: Phone : 9686812001 | B23: INVALID
A24: Name : Saranath kk
A25: Phone : 9092826599 | B25: CB | C25: SUNITA
A26: Name : Aman devkatte
A27: Phone : 8669182245 | B27: SWITCH OFF
A28: Name : Prataprao kishanrao kale
A29: Phone : 9673186210 | B29: NI
A30: Name : Prabhakar Tilve
A31: Phone : 9763068706 | B31: INTERESTED | C31: KAMINI
A32: Name : Gulshan lamba
A33: Phone : 9711665415 | B33: CB | C33: SHRUTI
A34: Name : asdf@sf.com
A35: Phone : 9962012546 | B35: SWITCH OFF
A36: Name : Utpal roy
A37: Phone : 7896572928 | B37: NI
A38: Name : Shajnavas
A39: Phone : 9388871114 | B39: INTERESTED | C39: VRADDHI
A40: Name : ERESH
...

Sheet 28-se3p-2024
A1: Client details | B1: Remark | C1: Emp.
A2: Name : K venkatesh
A3: Phone : 9441446419 | B3: LI
A4: Name : ബിനു P
A5: Phone : 7909106846 | B5: BUSY
A6: Name : Bijeeta
A7: Phone : 9801053080 | B7: NI
A8: Name : Madan
A9: Phone : 7411901829 | B9: NI
A10: Name : Sachin Nadkarni
A11: Phone : 9833126708 | B11: CB
A12: Name : Md Enus
A13: Phone : 9533750193 | B13: FT | C13: VOM
A14: Name : Bhanu Nailwal
A15: Phone : 9599953098 | B15: REPEAT
A16: Name : Deepak
A17: Phone : 8178563246 | B17: NPC
A18: Name : Prasanth
A19: Phone : 7356663593 | B19: SWITCH OFF
A20: Name : Vikas Kapoor
A21: Phone : 9910799666 | B21: FOLLO UP | C21: VOM
A22: Name : Hemant lakhe
A23: Phone : 9022139889 | B23: NPC
A24: Name : Prakaashh
A25: Phone : 8855000075 | B25: NPC
A26: Name : Maheswaran V
A27: Phone : 9111300510 | B27: FOLLO UP | C27: AMIT
A28: Name : Sharad patil
A29: Phone : 9096689389 | B29: NI
A30: Name : Yogish
A31: Phone : 9945208371 | B31: NC
A32: Name : chadramani Jadhav
A33: Phone : 8432004192 | B33: WRONG NO.
A34: Name : Prakasam
A35: Phone : 8754827611 | B35: LS
A36: Name : ,m , ,
A37: Phone : 9448526365 | B37: NPC
A38: Name : fasfdjfnwokn
A39: Phone : 9654785213 | B39: SWITCH OFF

Sheet 30-sep-2024
A1: Client details | B1: Remark | C1: Emp.
A2: Name : Bpk
A3: Phone : 8892585700 | B3: CD | C3: KAMINI
A4: Name : Kulesh Dhaneshrao Badwane
A5: Phone : 9764258488 | B5: INTERESTED | C5: RISHI
A6: Name : Harshal salve
A7: Phone : 8767199916 | B7: CD | C7: KAMINI
A8: Name : Mahesha. M
A9: Phone : 9611666930 | B9: FT | C9: RISHI
A10: Name : Pooja
A11: Phone : 9607761499 | B11: INTERESTED | C11: SUNITA
A12: Name : Bala
A13: Phone : 7708647884 | B13: NC
A14: Name : Jayshree goraksh chakane
A15: Phone : 7977640843 | B15: FT | C15: PAWAN
A16: Name : Raj barbar
A17: Phone : 9284852935 | B17: CB | C17: AYUSH
A18: Name : VIJAY TAYADE
A19: Phone : 9637217897 | B19: INTERESTED | C19: SUNITA
A20: Name : SURESH KUMAR
A21: Phone : 9095611138 | B21: SWITCH OFF
A22: Name : Shivaji Pendor
A23: Phone : 7620274600 | B23: BUSY
A24: Name : Karan
A25: Phone : 7768889006 | B25: FOLLOW UP | C25: RISHI
A26: Name : ashish wable
A27: Phone : 9146343814 | B27: INTERESTED | C27: AYUSH
A28: Name : Roshan
A29: Phone : 7208641489 | B29: CB | C29: SHRUTI
A30: Name : Mallikarjun
A31: Phone : 9845482584 | B31: NC
A32: Name : Preetham
A33: Phone : 9901528082 | B33: NPC
A34: Name : diraviam iyadurai
A35: Phone : 8667606434 | B35: NPC
A36: Name : HARDIK DARJI
A37: Phone : 7203008525 | B37: INTERESTED | C37: SHALINA
A38: Name : Nitto
A39: Phone : 9048846248 | B39: NPC
A40: Name : Abhishek malik
...

Sheet 01-10-2024
A1: CLIENT DETAILS | B1: REMARK | C1: EMP…
A2: Name : Suman kumar
A3: Phone : 7547091469 | B3: ft | C3: SHRUTI
A4: Name : ANTARA BASU Phone : 7890918019 | B4: intrusted | C4: SHRUTI
A5: Name : Anita Phone : 9986616116 | B5: ni
A6: Name : Mukesh Gaikwad Phone : 8412805050 | B6: cb
A7: Name : naveed Phone : 9343830277 | B7: CB
A8: Name : Kuldeep Phone : 8423230016 | B8: INTERESTED AFTER DIWALI | C8: CAPITAL ISSUE | D8: DHARMESH
A9: Name : Munna Phone : 9619718047 | B9: followup | C9: MAHENDRA
A10: Name : Dhanesh
A11: Phone : 7904188933 | B11: cb | C11: SHRUTI
A12: Name : Dhamapal gawai
A13: Phone : 8446688678 | B13: ft | C13: KHUSHI
A14: Name : Wali Phone : 9125813962 | B14: FT | C14: MAHENDRA
A15: Name : Vijay makode Phone : 7385876280 | B15: ft | C15: AMIT
A16: Name : Yusub Phone : 9898823457 | B16: CB | C16: SHRUTI
A17: Name : Vinod S
A18: Phone : 9945264280 | B18: ft | C18: AYUSH
A19: Name : JAYA KUMAR P V
A20: Phone : 9786874475 | B20: NPC
A21: Name : Mohammad MOTESHIM
A22: Phone : 8884077099 | B22: NPC
A23: Name : Aditya Phone : 7710877268 | B23: ft | C23: TANVI
A24: Name : Suraj b Phone : 9667956778 | B24: SWITCH OFF
A25: Name : Sunil kashinath khobragad Phone : 9923740702 | B25: NPC
A26: Name : Sundeep
A27: Phone : 9223519478 | B27: cb | C27: VOM
A28: Name : Ranjan Kumar Tiwari
A29: Phone : 9560580532 | B29: FT | C29: AMIT
A30: Name : Chandrashekar Phone : 9845560830 | B30: ft | C30: KAMINI
A31: Name : JANARDHAN Phone : 9380606060 | B31: NPC
A32: Name : Shankar Phone : 9894825738 | B32: ft | C32: AYUSH
A33: Name : Syam Phone : 9420808861 | B33: NPC
A34: Name : Santhosh p Phone : 8861117385 | B34: SWITCH OFF
A35: Name : ANANDAREUBEN R
A36: Phone : 8220954277 | B36: ft | C36: AMIT
A37: Name : Pravin Rokade Phone : 9740376692 | B37: intrusted | C37: KAMINI
A38: Name : Sajjad Phone : 9920666806 | B38: cb
A39: Name : Amal Phone : 7559006941 | B39: NC
A40: Name : VENKATESH SHA Phone : 8248272532 | B40: BUSY
...

Sheet 03-10-2024
A1: Client Details | B1: Remark | C1: Emp.
A2: Name : Prashant Galimath
A3: Phone : 7019122678
A4: Name : Sidhartha Sahoo Phone : 9348661747
A5: Name : Punit Desai Phone : 9823395213 | B5: WRONG
A6: Name : Manohar Dandu Phone : 9481872088 | B6: NPC
A7: Name : Kushal Phone : 8217331219 | B7: NI
A8: Name : Swamireddy Phone : 9949125322 | B8: NPC
A9: Name : Vinothkumar N Phone : 8610891551 | B9: REPEAT
A10: Name : Naveen Payal
A11: Phone : 9810972047 | B11: NPC
A12: Name : rohit kumaar Phone : 8409198769 | B12: INVALID
A13: Name : JAGADISH HARAGOLI Phone : 9901016660 | B13: NI
A14: Name : Bhima Phone : 9861606063 | B14: NI
A15: Name : Dalvir singh Phone : 9899629819 | B15: FT | C15: AKSHAY
A16: Name : Manish Phone : 8806380741 | B16: FT | C16: SANJAY
A17: Name : Tejas Thakur 1 Phone : 8975871687 | B17: NI
A18: Name : Mohan Shukla Phone : 9213092120 | B18: NPC
A19: Name : Sailin Kumar Babu Phone : 9437903581 | B19: CD
A20: Name : SUBHRAKANTI CHAKRABORTy Phone : 7031366643 | B20: NPC
A21: Name : Aman singh Phone : 7379028365 | B21: npc
A22: Name : raghavendra raghu Phone : 8310774730 | B22: ft | C22: SHRUTI
A23: Name : Nabu Phone : 9686449409 | B23: off
A24: Name : Indhu J R Phone : 9847120030 | B24: ni
A25: Name : Vilas Phone : 9926843459 | B25: npc
A26: Name : Siddiraju satyanarayana Phone : 9989760126 | B26: npc
A27: Name : Abhisek Mohanty Phone : 8260707003 | B27: INT | C27: SHIVAM | D27: 45947
A28: Name : Ajay varsolkar Phone : 9021888737 | B28: INT | C28: SHIVAM | D28: 45947 | E28: NOV
A29: Name : Nikhil Popat Jadhav Phone : 7021646159 | B29: npc
A30: Name : Mani Phone : 9943484262 | B30: ni
A31: Name : Nitin Borkar Phone : 9371559992 | B31: ft | C31: AMIT
A32: Name : Srinu Phone : 8179558967 | B32: intrusted | C32: SHRUTI
A33: Name : Vcgg Phone : 9078565434 | B33: busy
A34: Name : Lakshaya Phone : 8112235103 | B34: intrusted | C34: SUNITA
A35: Name : Sharma Mukesh Phone : 9601787874 | B35: npc
A36: Name : GAUTAM NASKAR Phone : 9748706997 | B36: FT | C36: AKSHAY
A37: Name : SHARAD KUMAR SONI Phone : 9423050750 | B37: ft 5LAKH | C37: KAMINI
A38: Name : Justin Phone : 8848180579 | B38: BUSY
A39: Name : Akshay Vaishnav Phone : 9145841162 | B39: cb | C39: AKSHAY
A40: Name : Priyadarshi Mohapatra Phone : 9937010003 | B40: npc
...

Sheet 04-10-2024
A1: CLIENTS DETAILS | B1: REMARK | C1: EMP…
A2: Name : Gagan
A3: Phone : 9176629689 | B3: FT | C3: AMIT
A4: Name : Dhanu Phone : 8328107240 | B4: BUSY
A5: Name : Anjini Phone : 9880802509 | B5: NI
A6: Name : Umer
A7: Phone : 7710874517 | B7: CB | C7: AKSHAY
A8: Name : ANANTH NAG Phone : 8830025059 | B8: BUSY
A9: Name : R MALKIYA RASALIN PRINCE
A10: Phone : 9486913582 | B10: CB | C10: SHRUTI
A11: Name : Sampad Rath
A12: Phone : 9438153376 | B12: PAID | C12: MAHENDRA
A13: Name : Niranjan
A14: Phone : 9150987181 | B14: NPC
A15: Name : Sameer
A16: Phone : 8280986957 | B16: BUSY
A17: Name : B G PATIL
A18: Phone : 9901491256 | B18: CB | C18: PAWAN
A19: Name : Ridh
A20: Phone : 9137325390 | B20: BUSY
A21: Name : Rudra Narayan
A22: Phone : 8984103115 | B22: NC
A23: Name : Dhjks
A24: Phone : 8888567128 | B24: SWITCH OFF
A25: Name : Tejas kothawade
A26: Phone : 8856967062 | B26: CB | C26: PAWAN
A27: Name : Abhijith GM
A28: Phone : 6366916567 | B28: BUSY
A29: Name : Subhash D. Pawar
A30: Phone : 8108741627 | B30: NPC
A31: Name : Aaaaaaaa
A32: Phone : 9411110001 | B32: NPC
A33: Name : Vaishali
A34: Phone : 9960687506 | B34: BUSY
A35: Name : RajaMohanKumar G N
A36: Phone : 9916768994 | B36: BUSY
A37: Name : MAMUN
A38: Phone : 9153007412 | B38: NI
A39: Name : Akd
A40: Phone : 9629344221 | B40: NPC
...

Sheet 05-10-2024
A1: CLIENTS DETAILS | B1: REMARK | C1: EMP…
A2: Name : Hitesh
A3: Phone : 9321471194 | B3: FOLLOW UP | C3: AYUSH
A4: Name : GOPALAKRISHNAN B
A5: Phone : 9884087735 | B5: BUSY
A6: Name : Seram
A7: Phone : 9566059500 | B7: SWITCH OFF
A8: Name : Xyzpvtltd
A9: Phone : 9999999999 | B9: WRONG NO
A10: Name : Naina Khamkar
A11: Phone : 9967664332 | B11: cb | C11: shalina
A12: Name : Khan Ahmed
A13: Phone : 9372241200 | B13: fund issue
A14: Name : Alok
A15: Phone : 7021984901 | B15: CB 8 | C15: AYUSH | D15: KAL CB
A16: Name : Vinay thakur
A17: Phone : 9682599981 | B17: CB | C17: SHRUTI
A18: Name : Ankit okuj
A19: Phone : 9595807966 | B19: INVALID
A20: Name : Anil Abhyankar
A21: Phone : 8261975761 | B21: WRONG NO
A22: Name : SIVAPRAKAKASAM Sivaprakasam
A23: Phone : 7667456575 | B23: NPC
A24: Name : P chinnasamy
A25: Phone : 9976826148 | B25: FOLLOW UP | C25: VOM
A26: Name : Dibakar
A27: Phone : 9922236769 | B27: FOLLOW UP | C27: VOM
A28: Name : Madhu Aravindh
A29: Phone : 9894744880 | B29: PAID | C29: AYUSH
A30: Name : Boopalan sampath | B30: FT
A31: Phone : 7358028986 | B31: FT | C31: AMIT
A32: Name : Vgr
A33: Phone : 9640223817 | B33: SWITCH OFF
A34: Name : Vijet naik
A35: Phone : 8867223268 | B35: BUSY
A36: Name : Jhilmil Pradhan
A37: Phone : 7459035938 | B37: BUSY
A38: Name : ASHUTOSH VIJAY BAL
A39: Phone : 9821942255 | B39: NPC
A40: Name : Dattatray Thorat
...

Sheet 07-10-2024
A1: CLIENTS DETAILS | B1: REMARK | C1: EMP…
A2: Name : Sadashiv Dhumal
A3: Phone : 7058327430 | B3: NI
A4: Name : Pradeep tiwari
A5: Phone : 9311674245 | B5: NI
A6: Name : Gopi
A7: Phone : 7051021484 | B7: NI
A8: Name : R
A9: Phone : 9444558520 | B9: NC
A10: Name : Parkash Chander
A11: Phone : 7015227719 | B11: NI
A12: Name : Jayesh
A13: Phone : 9975752279 | B13: BUSY
A14: Name : Nanaware Gaurav Hanumant | B14: FT
A15: Phone : 9561603872 | B15: FT | C15: SHRUTI
A16: Name : Dr SUNDER
A17: Phone : 9486142252 | B17: INTERESTED
A18: Name : Rahul Rankesh
A19: Phone : 8100568442 | B19: BUSY
A20: Name : Rajimol
A21: Phone : 9495195878 | B21: NC
A22: Name : Disha bhatt
A23: Phone : 8050868056 | B23: NPC
A24: Name : Hitesh Zamad
A25: Phone : 8625845494 | B25: WRONG NO
A26: Name : Haribaskaran
A27: Phone : 9003776747 | B27: LI
A28: Name : Shreenivasa
A29: Phone : 8880742296 | B29: BUSY
A30: Name : Yash suryawanshi
A31: Phone : 9021014929 | B31: CB | C31: VISHNU | D31: NPC
A32: Name : Sukhdeep Singh
A33: Phone : 9811325235 | B33: NI
A34: Name : Kumaravel B
A35: Phone : 7397380718 | B35: NC
A36: Name : Ram darade
A37: Phone : 8208481720 | B37: BUSY
A38: Name : Sanjay Kumar Vishwakarma
A39: Phone : 7087568234 | B39: BUSY
A40: Name : Veeraju
...

Sheet EXPENSIVE  
A2: 96250 | B2: MOBILE +COVER
A3: 800
A4: 820 | B4: BANER
A5: 700 | B5: NASTA
A6: 3350 | B6: EXPENS | E6: 203978 | F6: BILL + RENT
A7: 2000 | B7: EXPENS | E7: 16895 | F7: BILL + EXPENS
E8: 7000 | F8: BILL
A9: 840 | B9: EXPENS | I9: =132601+227873 -> 360474
A10: 1330 | B10: EXPENS
A11: 1806 | B11: EXPENS
A13: 500 | B13: EXPENS
A14: 10500 | B14: OFFICE PARTY
A15: 1500 | B15: OFFICE PARTY
A16: 500 | B16: EXPENS
A17: 100 | B17: EXPENS
K18: =1156400-200000 -> 956400
A19: 1160 | B19: EXPENS
A20: 850 | B20: EXPENS
A21: 1300 | B21: EXPENS
A22: 880 | B22: EXPENS
A23: 3850 | B23: EXPENS
A24: 1185 | B24: EXPENS
A25: 2100 | B25: EXPENS
A26: 280 | B26: EXPENS
F36: TOTAL LEADS - 53
F37: Date -18.10.24
F38: FT | G38: 6
F39: INTERESTED | G39: 1
F40: FOLLOWUP | G40: 3
F41: CB | G41: 0
F42: BUSY | G42: 12
F43: CD
F44: NI | G44: 5
F45: NPC | G45: 4
F46: OTHERS | G46: 23

Sheet FT 26-10-24
A1: CLIENTS DETAIL | B1: REMARK | C1: INVESTMENT | D1: REMARK
A2: Name : Varsha Seth | I2: TOTAL LEADS - 386
A3: Phone : 9163605584 | B3: FT | C3: 15K | D3: VISHNU | I3: Date -26.10.24
A4: Name : Ravi Bhasamre | I4: FT | J4: 11
A5: Phone : 7666799660 | B5: CB | D5: VISHNU | I5: INTERESTED | J5: 7
A6: Name : Mamta rana | I6: FOLLOWUP | J6: 3
A7: Phone : 9582978824 | B7: FT | C7: 20K | D7: VISHNU | I7: CB | J7: 4
A8: Name : Goga | I8: BUSY | J8: 62
A9: Phone : 9604057974 | B9: FT | C9: 40K | D9: KAMINI | I9: CD | J9: 36
A10: Name : Syed Mohiuddin Phone : 9866790632 | B10: CB | D10: KAMINI | I10: NI | J10: 84
A11: Name : Srinivas Rao | I11: NPC | J11: 104
I12: OTHERS | J12: 79
A13: Janesh 8169098400 | B13: FT | C13: 5LAC CAPITAL
A14: Name : MD HUSAIN
A15: Phone : 8860197989 | B15: FT | D15: VIJAY
A16: Name : Satyajit moharana
A17: Phone : 7978965049 | B17: INTERESTED | D17: SHALINA
A18: Name : Yuvraj
A19: Phone : 9555527783 | B19: FT | D19: AMIT
A20: Name : Vijay Kumar Tak
A21: Phone : 8003933837 | B21: INTERESTED | D21: MAHENDRA
A22: Name : Dhamapal gawai
A23: Phone : 8446688678 | B23: INTERESTED | D23: MAHENDRA
A24: Name : Pramod
A25: Phone : 7021070412 | B25: CB MONDAY
A26: Name : Ramesh Sundaram
A27: Phone : 7418944330 | B27: FT | D27: RISHI
A28: Name : Swapnil Phone : 8208453115 | B28: INTERESTED | D28: RISHI
A29: Name : Umer
A30: Phone : 7710874517 | B30: FOLLOW UP | D30: RISHI
A31: Name : Dalvir singh Phone : 9899629819 | B31: FOLLOW UP | D31: RISHI
A32: Name : Aneeshbala
A33: Phone : 8921297800 | B33: FUTURE INTERESTED | D33: SUNITA
A34: Name : Shubham More
A35: Phone : 8830638246 | B35: CB | D35: MAHENDRA
A36: Name : Srinivasamoorthy sharma
A37: Phone : 8762555960 | B37: FT | D37: AMIT
A38: Name : Ramachandran
A39: Phone : 9500046725 | B39: INTERESTED | D39: AYUSH
A40: Name : Babu
...

Sheet 3.10.24
A1: CLIENTS DETAILS | B1: REMARK | C1: EMP..
A2: Name : Avinash Parwe
A3: Phone : 8149219519 | B3: NC
A4: Name : Abdul nasar
A5: Phone : 7909200000 | B5: SWITCH OFF
A6: Name : Vishu Shinde
A7: Phone : 9284220551 | B7: NPC
A8: Name : Manoj Kumar jain
A9: Phone : 9650773208 | B9: AFTER M. | C9: RISHI
A10: Name : ANUP KR GHOSH
A11: Phone : 9851156053 | B11: FT | C11: AMIT
A12: Name : SHAFIN MAHIDA
A13: Phone : 7016490230 | B13: INTERESTED | C13: RAJ
A14: Name : Nnn
A15: Phone : 9994774831 | B15: NPC
A16: Name : Vivek Rathi
A17: Phone : 7682969855 | B17: AMIT
A18: Name : Rajshekhar Patil
A19: Phone : 9743617975 | B19: NR
A20: Name : Dilip chakraborty
A21: Phone : 7278567738 | B21: NI
A22: Name : magan
A23: Phone : 9368022127 | B23: NI
A24: Name : Ravi A R
A25: Phone : 9900289231 | B25: NPC
A26: Name : Kranti
A27: Phone : 7656055500 | B27: NC
A28: Name : Avinash K
A29: Phone : 6366346002 | B29: NPC
A30: Name : Shijo george
A31: Phone : 7736023155 | B31: BUSY
A32: Name : Aditya khutwad
A33: Phone : 9226304210 | B33: CB | C33: PAWAN
A34: Name : Dattatraya Satpute
A35: Phone : 9226888232 | B35: NPC
A36: Name : Emaer
A37: Phone : 8788501061 | B37: LI
A38: Name : Gholap kishor
A39: Phone : 9579529193 | B39: NPC
A40: Name : Sanket Junghare
...

Sheet 08-10-2024
A1: CLIENTS DETAILS | B1: REMARK | C1: INVESTMENT | D1: EMP…
A2: Name : amit chouhan
A3: Phone : 7738553566 | B3: CB EVENING | D3: KAMINI
A4: Name : Sipun kumar
A5: Phone : 7008435883 | B5: NPC | D5: RISHI
A6: Name : Lalit
A7: Phone : 9930218264 | B7: CB 12 PM | D7: VOM
A8: Name : Pavan
A9: Phone : 8805682743 | B9: NPC
A10: Name : Akash3591
A11: Phone : 8073431232 | B11: CB | D11: AMIT
A12: Name : Murali
A13: Phone : 9629630807 | B13: INTERESTED | D13: KAMINI
A14: Name : Ankur
A15: Phone : 9729863010 | B15: NPC
A16: Name : Swoyamprava
A17: Phone : 8249285172 | B17: BUSY
A18: Name : adarsh
A19: Phone : 9860410411 | B19: NPC
A20: Name : Harshit chauhan
A21: Phone : 8866338831 | B21: NI
A22: Name : Shiv Shankar
A23: Phone : 6387167813 | B23: INTERESTED | D23: KAMINI
A24: Name : Haridas N
A25: Phone : 9142198228 | B25: NI
A26: Name : Palla vinod kumar
A27: Phone : 8186824781 | B27: BUSY
A28: Name : B.A Srinivasa
A29: Phone : 8553468558 | B29: BUSY
A30: Name : Saikumar
A31: Phone : 9182030324 | B31: BUSY
A32: Name : Habibi
A33: Phone : 9849662306 | B33: NI
A34: Name : Vipul
A35: Phone : 9373116657 | B35: PAYMENT DONE | D35: SUNITA
A36: Name : muzammil
A37: Phone : 9765552403 | B37: Ni
A38: Name : Arin
A39: Phone : 7028893735 | B39: FUTURE INTERESTED
A40: Name : Ashish sahani
...

Sheet 10-10-2024
A1: CLIENTS DETAILS | B1: REMARK | C1: INVESTMENT | D1: EMP…
A2: Name : Jacquiline
A3: Phone : 8848527437 | B3: CB | D3: SHRUTI
A4: Name : Kavitha G
A5: Phone : 9562547654 | B5: INVALID
A6: Name : Ashish kumar Barik
A7: Phone : 9090560560 | B7: Clinic ka number h ye uske
A8: Name : Pradeep mandal
A9: Phone : 7894516213 | B9: FOLLOW UP | C9: 12 DAYS | D9: AYUSH
A10: Name : Tushar suryawanshi
A11: Phone : 7666285848 | B11: SF
A12: Name : Tapan
A13: Phone : 9348615447 | B13: FT | C13: 25k stock intraday | D13: YASH
A14: Name : Sumeet
A15: Phone : 8178022878 | B15: FT | D15: RAJ
A16: Name : Ravi .
A17: Phone : 8217768304 | B17: INVALID
A18: Name : Shivam bhalavi
A19: Phone : 9699445516 | B19: CB TOMORROW | D19: RITU
A20: Name : Bishwa
A21: Phone : 7868553656 | B21: INVALID
A22: Name : Vasanth
A23: Phone : 9344052172 | B23: SAID DONT CALL ME
A24: Name : Ashokkumarbehera
A25: Phone : 7008048755 | B25: NPC
A26: Name : Knashswell | B26: FT
A27: Phone : 9560842105 | B27: FT | C27: 50K | D27: SHRUTI
A28: Name : Shubham gadkar
A29: Phone : 9403327202 | B29: BUYS
A30: Name : Rajesh Singh
A31: Phone : 9930099505 | B31: INTERESTED | C31: 25K | D31: YASH
A32: Name : Master
A33: Phone : 6005000591 | B33: NI
A34: Name : Srinivas Rao
A35: Phone : 7008535768 | B35: FOLLOW UP | D35: VOM
A36: Name : Vmk | B36: FT
A37: Phone : 9943282325 | B37: FT | C37: 50K | D37: AMIT
A38: Name : POORAJAN
A39: Phone : 9600770309 | B39: FOLLOW UP | C39: option/1 lakh/ expectation : 5 Lakhs | D39: RISHI
A40: Name : Jyoti Singh
...

Sheet 09-10-2024
A1: CLIENTS DETAILS | B1: REMARK | C1: INVESTMENT | D1: EMP…
A2: Name : Arif | B2: FT
A3: Phone : 9702858602 | B3: FT | C3: 5 LAKH | D3: RITU
A4: Name : rajappan
A5: Phone : 9847505265 | B5: SF
A6: Name : Premdas
A7: Phone : 9637098125 | B7: SF | D7: KAMINI
A8: Name : Aiman Badane | B8: FT
A9: Phone : 9373778518 | B9: FT | D9: AMIT
A10: Name : sarvesh43198@gmailcom
A11: Phone : 9769543732 | B11: NPC
A12: Name : Rappa
A13: Phone : 9000000000 | B13: invalid
A14: Name : Sandi
A15: Phone : 7982931280 | B15: NI
A16: Name : Abhay Kumar
A17: Phone : 9560165472 | B17: FOLLOW UP | D17: KAMINI
A18: Name : Akash L
A19: Phone : 8197059648 | B19: NI
A20: Name : Ayyappan
A21: Phone : 8015120392 | B21: invalid
A22: Name : Manuel M.S
A23: Phone : 9847169683 | B23: NPC
A24: Name : Manoj Gadkari
A25: Phone : 9223209996 | B25: NPC
A26: Name : Jabadurai
A27: Phone : 8668176541 | B27: NPC
A28: Name : Karthik
A29: Phone : 9790875570 | B29: SF
A30: Name : AASHISH CHATTAR
A31: Phone : 9579768205 | B31: NI
A32: Name : Sanjay Sharma
A33: Phone : 9438143002 | B33: NI
A34: Name : Bandi koteswararao
A35: Phone : 9000366247 | B35: PAID
A36: Name : Ajeetesh
A37: Phone : 8018111810 | B37: INTERESTED | D37: RAJ
A38: Name : Xy
A39: Phone : 9899967999 | B39: NI
A40: Name : Bhavik | B40: FT
...

Sheet 11-10-2024
A1: CLIENTS DETAIL | B1: REMARK | C1: INVESTMENT | D1: EMP…
A2: Name : Sivara
A3: Phone : 7444450022 | B3: INVALID
A4: Name : Husain devendra madiwal
A5: Phone : 7738721537 | B5: BUSY
A6: Name : Santosh
A7: Phone : 9962292567 | B7: SF
A8: Name : Karthip
A9: Phone : 9578414221 | B9: NPC
A10: Name : Ajay prataprao more
A11: Phone : 9890817689 | B11: NI
A12: Name : Ponmaniraja
A13: Phone : 9952770767 | B13: BUSY
A14: Name : Deepak kumar
A15: Phone : 9911261493 | B15: NPC
A16: Name : Nareshkumar
A17: Phone : 9962447117 | B17: NPC
A18: Name : Sandeep Rode
A19: Phone : 7276929999 | B19: INTERESTED | D19: SUNITA
A20: Name : Mangginlen Haokip
A21: Phone : 8787774316 | B21: NPC
A22: Name : srinivasa
A23: Phone : 8141382952 | B23: NI
A24: Name : Shanmuga
A25: Phone : 9524371155 | B25: CD WC
A26: Name : Sushant ananda awale
A27: Phone : 9766933620 | B27: NC
A28: Name : Varsha Seth
A29: Phone : 9163605584 | B29: FOLLOW UP | D29: VIKASH
A30: Name : Virender Singh Negi | B30: FT
A31: Phone : 9915350144 | B31: FT | C31: 10K | D31: VOM
A32: Name : Suraj rajye
A33: Phone : 8975857093 | B33: INTERESTED | D33: SUNITA
A34: Name : P L MANOJ
A35: Phone : 9746817464 | B35: NPC
A36: Name : Sandeep javare
A37: Phone : 7420838472 | B37: NPC | D37: VOM
A38: Name : Himanshu Rajbhar
A39: Phone : 7558707503 | B39: BUSY
A40: Name : Vijayakanth Rama
...

Sheet 14-10-2024
A1: CLIENTS DETAILS | B1: REMARK | C1: INVESTMENT | D1: EMP…
A2: Name : Sagar naswa
A3: Phone : 9654742902 | B3: CB | D3: RISHI
A4: Name : Sumata sethi
A5: Phone : 8018575373 | B5: SF
A6: Name : Ravi Teja Pokala
A7: Phone : 9177235051 | B7: FOLLOW UP | D7: AMIT
A8: Name : prakash Ananda kandre
A9: Phone : 7028408479 | B9: NPC
A10: Name : Sunild
A11: Phone : 9423008902 | B11: NPC
A12: Name : Thyagarajan
A13: Phone : 9940693948 | B13: INTERESTED | D13: RITU
A14: Name : S.siva Sreekanth
A15: Phone : 9441030128 | B15: NI
A16: Name : dsfg
A17: Phone : 9856321456 | B17: INVALID
A18: Name : Nivash Kumar
A19: Phone : 6382223680 | B19: NPC | C19: 14/10/2024
A20: Name : Babu
A21: Phone : 6379344544 | B21: INTERESTED | C21: REPEAT | D21: SUNITA
A22: Name : ramesha
A23: Phone : 9964502012 | B23: NI
A24: Name : Hari | B24: FT
A25: Phone : 7276016008 | B25: FT | C25: 20K | D25: KAMINI
A26: Name : HIRAN
A27: Phone : 9535214870 | B27: NI | C27: 10/15/2024 MORNING | D27: VOM
A28: Name : nilo
A29: Phone : 8788507821 | B29: FOLLOW UP | C29: REPEAT NO. | D29: AMBRISH
A30: Name : sonu shaikh
A31: Phone : 7757002813 | B31: NI
A32: Name : A.VALLINAYAGAM | B32: FT
A33: Phone : 9344452106 | B33: FT | D33: Harendra
A34: Name : dfasf
A35: Phone : 9885486258 | B35: NPC
A36: Name : Vishwaja
A37: Phone : 7507937679 | B37: INTERESTED | D37: VIJAY
A38: Name : rakesh rampa
A39: Phone : 9440939824 | B39: PAID | D39: KAMINI
A40: Name : Chander Kant Sharma
...

Sheet 15-10-24
A1: CLIENTS DETAILS | B1: REMARK | C1: INVESTMENT | D1: EMP….
A2: Name : Abdul Qadir Ansari
A3: Phone : 8660022799 | B3: PAID | D3: VIJAY
A4: Name : Deepak talpe | I4: TOTAL LEADS - 63
A5: Phone : 9028239509 | B5: NC | I5: Date -15.10.24
A6: Name : Yash Choudhary | I6: FT | J6: 8
A7: Phone : 9990644107 | B7: NPC | I7: INTERESTED | J7: 2
A8: Name : Uc narayana | I8: FOLLOWUP | J8: 4
A9: Phone : 9959849623 | B9: NPC | I9: CB | J9: 8
A10: Name : Dd | I10: BUSY | J10: 3
A11: Phone : 9546078512 | B11: NI | I11: NI | J11: 6
A12: Name : Mukesh Ahire | I12: NPC | J12: 18
A13: Phone : 8356906595 | B13: CB 3:30 | D13: AYUSH | I13: OTHERS | J13: 16
A14: Name : Sudesh
A15: Phone : 9967361987 | B15: NI
A16: Name : Sudheer Kumar
A17: Phone : 9611723975 | B17: INTERESTED | D17: VIJAY
A18: Name : Dav
A19: Phone : 6360161965 | B19: DETAIL SEND | D19: RISHI
A20: Name : Tarkeshwar Jain
A21: Phone : 9314531886 | B21: SF
A22: Name : Santosha
A23: Phone : 8105641535 | B23: NI
A24: Name : Neee
A25: Phone : 8446227696 | B25: NPC
A26: Name : thakur
A27: Phone : 8906014544 | B27: NPC | D27: VIJAY
A28: Name : Vandana Soni
A29: Phone : 9004087575 | B29: NI
A30: Name : S PRIYA LAKSHMI
A31: Phone : 8807585539 | B31: INVALID
A32: Name : giri reddy
A33: Phone : 8438378546 | B33: INTERESTED | D33: KAMINI
A34: Name : Mukesh kumawat
A35: Phone : 7014128173 | B35: NPC
A36: Name : Chandan chakma
A37: Phone : 8277634966 | B37: INTERESTED | C37: 10K
A38: Name : Subrat patra | B38: FT
A39: Phone : 7377636347 | B39: FT | D39: SHALINA
A40: Name : Birender Govil
...

Sheet OLD 
A1: Name : Kuldeep Phone : | B1: 8423230016 | C1: Fund issue after Diwali start | D1: DHARMESH
A2: 1-client name_bhushan /number_/ investment- 50k | B2: 9897688442 | D2: SHRUTI
A3: 2-prajwal / 40k | B3: 7517834510
A4: Name : Yuvika
A5: Phone : 9482790043 | B5: =RIGHT(A5,10) -> 9482790043 | C5: INTERESTED | D5: RAJ
A6: Name kishore Mobile No. 9937467174 Service - Stock-Cash | C6: FOLLOW UP | D6: MAHENDRA
A7: Name : victor jayaraj S
A8: Phone : 7904773882 | C8: INTERESTED | D8: DHARMESH
A9: Name Ravi Mobile No. 9740577772 Service - Stock-Option | C9: FOLLOW UP | D9: MAHENDRA
A10: Name kishore Mobile No. 9937467174 Service - Stock-Cash | C10: FOLLOW UP | D10: MAHENDRA
A11: Name Amritha Ajaykumar Mobile No. 9747871316 Service - Stock-Cash | C11: CB | D11: MAHENDRA
A12: Name Terim Mobile No. 8529938236 Service - Stock-Cash - Stock-Option | C12: INTERESTED | D12: MAHENDRA
A13: Name Sumit Mobile No. 8669099741 Service - Stock-Cash - Stock-Future - Stock-Option -- | C13: INTERESTED | D13: MAHENDRA
A15: 15/10/2024
A17: Name Shantanu Mobile No. 9082987990 Services Option Nifty Bank Nifty | C17: TOMORROW AFT MARKET | D17: DHARMESH
A18: Name Pankaj Palariya Mobile No. 7819007059 Services Stock-Cash | C18: FT | D18: SHALINA
A19: Name Kuber Mobile No. 09611572903 Services Option Nifty Bank Nifty
A20: [ SELF TRADER , 3 MONTH , INDEX OPTION , FREE TRIAL , 2 LAKH , ] FREE TRIAL | D20: KAMINI
A21: Dear:Bhupendra Rathod Phone: 9673236770 interested \ stock only | C21: INTERESTED | D21: AMAN
A22: Name : Rahul kumbalkar Phone : 7587794750 ft | C22: FT | D22: RITU
A23: Rp 9007732825 cash 50k Kolkata FT | C23: FT | D23: RITU
A24: Arindam 7980708375 cash 1lac kolkata ft | C24: FT | D24: RITU
A25: Tabrez 9845122348 all seg. Banglore mahendra ft | C25: FT | D25: RITU
A26: Rathiranjan 9831971649 cash 50k call back 5 bje | C26: cb 5 | D26: RITU
A28: 16/10/2024
A29: 1-client name_arbaz /number_9845473520/ investment-50k
A30: 2-bijender/ 8900311480/ 50k
A31: Keerthan Mobile No. 7975307707 interested | C31: SUNITA
A33: 19/10/2024
A34: deepak MOBILE: 9588056821 | C34: KAMINI
A38: Name : Sandeep Rode
A39: Phone : 7276929999 | C39: INTERESTED | D39: SUNITA
A40: Name : Suraj rajye
A41: Phone : 8975857093 | C41: INTERESTED | E41: SUNITA
A42: Name : SAJIN RAJ
A43: Phone : 8122585058 | C43: INTERESTED | E43: SUNITA
A44: Name : bodapati pavan kumar
A45: Phone : 6309343938 | C45: FT | D45: 30K | E45: YASH
A46: Name : Santosh Sharma
A47: Phone : 8999895507 | C47: INTERESTED | D47: SUNITA
...

Sheet 16-10-24
A1: CLIENTS DETAILS | B1: REMARK | C1: INVESTMENT | D1: EMP….
A2: Name : nrusingh | B2: FT | G2: 14 no. mobile | H2: yadvender
A3: Phone : 8917558456 | B3: FT | C3: 2LAC | D3: AMIT
A4: CC
A5: Phone : Name : Tanish Phone : 6380237495 | B5: NI | G5: TOTAL LEADS - 74
A6: Name : Jeeva | G6: Date -16.10.24
A7: Phone : 9962154579 | B7: FOLLOW UP | D7: VISHNU | G7: FT | H7: 11
A8: Name : ABHISHEK SINGH | G8: INTERESTED | H8: 1
A9: Phone : 7007413592 | B9: INVALID | G9: FOLLOWUP | H9: 7
A10: Name : Rizwan Ali | G10: CB | H10: 6
A11: Phone : 9718562973 | B11: NI | G11: BUSY | H11: 3
A12: Name : AshokSK | G12: NI | H12: 8
A13: Phone : 8618344536 | B13: NPC | G13: NPC | H13: 13
A14: Name : Somasundaran Kulakkattu Palengara | G14: OTHERS | H14: 26
A15: Phone : 9744612643 | B15: NI
A16: Name : Suji
A17: Phone : 8328311145 | B17: NI
A18: Name : Dillibabu
A19: Phone : 9448289351 | B19: NI
A20: Name : TEJAS Hirachand Patil
A21: Phone : 9029409611 | B21: BUSY
A22: Name : Prajakta Barde | B22: FT
A23: Phone : 7796412155 | B23: FT | C23: 10K CAPITAL | D23: KAMINI
A24: Name : Kazi irfan
A25: Phone : 9820284445 | B25: INVALID
A26: Name : Ajinkya
A27: Phone : 8422993587 | B27: NI
A28: Name : Mahendran
A29: Phone : 8807174671 | B29: INVALID
A30: Name : Meghraj
A31: Phone : 9422733029 | B31: FOLLOW UP | D31: VIKASH
A32: Name : Sudharsan r
A33: Phone : 6282317769 | B33: INTERESTED | D33: SUNITA
A34: Name : Veena G R
A35: Phone : 8884980333 | B35: FOLLOW UP | D35: RISHI
A36: Name : Ctree
A37: Phone : 7755578855 | B37: INVALID
A38: Name : Sairqk
A39: Phone : 9487868621 | B39: NPC
A40: Name : Biju
...

Sheet 18-10-24
A1: CLIENTS DETAIL | B1: REMARK | C1: INVESTMENT | D1: REMARK
A2: Name : UJJWAL KUMAR SINGH | H2: TOTAL LEADS - 53
A3: Phone : 8130838918 | B3: FT | D3: AJAY | E3: 17/12/2024 | H3: Date -18.10.24
A4: Name : PK Rohira | B4: FT | H4: FT | I4: 6
A5: Phone : 9891337979 | B5: FT | D5: SHRUTI | H5: INTERESTED | I5: 1
A6: Name : Sreenivasarao | B6: FT | H6: FOLLOWUP | I6: 3
A7: Phone : 9705910889 | B7: FT | C7: 50K | D7: AMIT | H7: CB | I7: 0
A8: Name : Manda | H8: BUSY | I8: 12
A9: Phone : 8180876803 | B9: NI | D9: KAMINI | H9: NI | I9: 5
A10: Name : Satender Kumar Gautam | H10: NPC | I10: 4
A11: Phone : 9013401637 | B11: SF | D11: AYUSH | H11: OTHERS | I11: 23
A12: Name : Siddarth K S
A13: Phone : 7204542910 | B13: INVALID | D13: RAJ
A14: Name : Sai priya Chejarla
A15: Phone : 8179115271 | B15: NI | D15: VIJAY
A16: Name : Vaibhav
A17: Phone : 9325161891 | B17: NI | D17: KAMINI
A18: Name : Sundar n
A19: Phone : 8610974253 | B19: LI | D19: AMIT
A20: Name : Sanjayk
A21: Phone : 7008040769 | B21: NPC | D21: RISHI
A22: Name : Naveena Kumara M
A23: Phone : 6382294922 | B23: PAID | D23: VOM
A24: Name : Raj1
A25: Phone : 9494949494 | B25: INVALID | D25: AYUSH
A26: Name : Lalitvijay kumar | B26: FT
A27: Phone : 8448621522 | B27: FT | C27: 25K | D27: VISHNU
A28: Name : BHAVIN VADHAR | B28: FT
A29: Phone : 9819100370 | B29: FT | C29: 50K | D29: KAMINI
A30: Name : शुभापुजरी
A31: Phone : 8263909574 | B31: BUSY | D31: VISHNU | J31: F
A32: Name : Rohini Mahadik
A33: Phone : 9082409412 | B33: PAID | D33: RISHI
A34: Name : Raghunathan R
A35: Phone : 9940674865 | B35: PAYMENT DONE | D35: AMIT
A36: Name : Ravi Ranjan Sinha
A37: Phone : 8303739070 | B37: NI | D37: RAJ
A38: Name : Vigneshladda
A39: Phone : 9840988999 | B39: BUSY | D39: AMIT
A40: Name : Aarti jadhav
...

Sheet 17-10-24
A1: CLIENTS DETAILS | B1: REMARK | C1: INVESTMENT | D1: EMP…
A2: Name : Vinod | H2: TOTAL LEADS - 82
A3: Phone : 9632106156 | B3: BUSY | D3: RISHI | H3: Date -17.10.24
A4: Name : Venkataraju | H4: FT | I4: 11
A5: Phone : 8105930977 | B5: NPC | D5: RAJ | H5: INTERESTED | I5: 5
A6: Name : Rajath R | H6: FOLLOWUP | I6: 8
A7: Phone : 8123393957 | B7: PAID | D7: VISHNU | H7: CB | I7: 5
A8: Name : Maruthi J | H8: BUSY | I8: 14
A9: Phone : 6360061216 | B9: BUSY | D9: AMIT | H9: NI | I9: 9
A10: Name : Barundeep Singh | H10: NPC | I10: 14
A11: Phone : 9459622663 | B11: FOLLOW UP | D11: AYUSH | H11: OTHERS | I11: 18
A12: Name : Dharmesh
A13: Phone : 9773292801 | B13: NI | D13: KAMINI
A14: Name : Godwin joseph
A15: Phone : 8108026556 | B15: NI | D15: SHALINA
A16: Name : Manoj H L
A17: Phone : 8050221701 | B17: FOLLOW UP | C17: 50K | D17: RC
A18: Name : Raj bhalkar
A19: Phone : 7887875544 | B19: CB | D19: KAMINI
A20: Name : Prajwal Sharma
A21: Phone : 9036105632 | B21: FOLLOW UP | D21: KAMINI
A22: Name : Pradip Balasaheb pawar
A23: Phone : 7447565730 | B23: NPC | D23: VISHNU
A24: Name : Arul
A25: Phone : 9095947066 | B25: SF | D25: VISHNU
A26: Name : Vedant
A27: Phone : 9922229343 | B27: NI | D27: SHALINA
A28: Name : Akash Mayandibharathi
A29: Phone : 9655541772 | B29: BUSY | C29: REPEAT NO. | D29: RISHI
A30: Name : Arhaan
A31: Phone : 9964932290 | B31: NPC | D31: KAMINI
A32: Name : Mayur kharat
A33: Phone : 9158003389 | B33: SF | D33: VIJAY
A34: Name : HARDIK KOTHARI
A35: Phone : 7666999669 | B35: PAYMENT DONE | D35: VIKASH
A36: Name : Arjun Thorat
A37: Phone : 9309785511 | B37: BUSY | D37: RAJ
A38: Name : jameer
A39: Phone : 9000488900 | B39: NI | D39: MAHENDAR
A40: Name : Lakshmikanth
...

Sheet 19-10-24
A1: CLIENTS DETAILS | B1: REMARK | C1: INVESTMENT | D1: EMP…
A2: Name : KPS KUMAR | H2: TOTAL LEADS - 33
A3: Phone : 9344406219 | B3: PAID | D3: RISHI | H3: Date -19.10.24
A4: Name : samar jyoti patar | B4: FT | H4: FT | I4: 6
A5: Phone : 7569415264 | B5: FT | C5: 30K | D5: AMIT | H5: INTERESTED | I5: 3
A6: Name : Dr. Rahul Kathariya | H6: FOLLOWUP | I6: 1
A7: Phone : 8983370741 | B7: FOLLOW UP | D7: VOM | H7: CB | I7: 2
A8: Phone : Name : samar jyoti patar | B8: FT | H8: BUSY | I8: 3
A9: Phone : 7569415264 | B9: FT | C9: 30K | D9: AMIT | H9: NI | I9: 1
A10: Name : Kuppusamy | B10: FT | H10: NPC | I10: 9
A11: Phone : 9944611537 | B11: FT | D11: RISHI | H11: OTHERS
A12: Name : Amol pawar
A13: Phone : 8668453535 | B13: CB | D13: VOM
A14: Name : Manja
A15: Phone : 9398647784 | B15: NPC | C15: REPEAT | D15: VISHNU
A16: Name : Gokul Krishna
A17: Phone : 7736785886 | B17: CD | D17: AMIT
A18: Name : Vijay singh
A19: Phone : 9650471000 | B19: NI | D19: KAMINI
A20: Name : Gokul Krishna
A21: Phone : 7736785886 | B21: BUSY | D21: AMIT
A22: Name : Titus Dsouza
A23: Phone : 9167193636 | B23: NPC | D23: VISHNU
A24: Name : Tanish
A25: Phone : 6380237495 | B25: NPC | D25: AMBRISH
A26: Name : Aditya Nanda
A27: Phone : 8439956966 | B27: NC | D27: KAMINI
A28: Name : Chandra Mohan
A29: Phone : 7989567987 | B29: BUSY | D29: AMIT
A30: Name : Kg ykxx vvjc
A31: Phone : 6655544565 | B31: INVALID | D31: VISHNU
A32: Name : Abhishek m b | B32: FT
A33: Phone : 8762314350 | B33: FT | C33: 1LAC | D33: AMIT
A34: Name : Manpreet Kaur
A35: Phone : 9717518277 | B35: INTERESTED | C35: NEXT MOUNTH | D35: KAMINI
A36: Name : chandru
A37: Phone : 9353414891 | B37: CB 4PM | D37: VOM
A38: Name : Rajesh Kumar panda
A39: Phone : 8917445849 | B39: FOLLOW UP | D39: VISHNU
A40: Name : Dharmendra
...

Sheet TODAY 21-10-24
A1: CLIENTS DETAILS | B1: REMARK | C1: INVESTMENT | D1: EMP… | G1: TOTAL LEADS - 59
A2: Name : Mahima Bisen 21 | G2: Date -21.10.24
A3: Phone : 8770310812 | B3: NI | D3: KAMINI | G3: FT | H3: 8
A4: Name : Chinmay Sethiya | G4: INTERESTED | H4: 1
A5: Phone : 8122051870 | B5: NI | D5: KAMINI | G5: FOLLOWUP | H5: 3
A6: Name : Baskar7982 | G6: CB | H6: 6
A7: Phone : 9994875586 | B7: NI | D7: AYUSH | G7: BUSY | H7: 4
A8: Name : Parmeshwar Shinde | G8: CD | H8: 5
A9: Phone : 9850866243 | B9: BUSY | D9: JITENDRA | G9: NI | H9: 9
A10: Name : Gaurav Upadhyay | G10: NPC | H10: 17
A11: Phone : 9873983990 | B11: CB EVENING | D11: RISHI | G11: OTHERS | H11: 6
A12: Name : Atri
A13: Phone : 9538162322 | B13: NI | C13: REPEAT | D13: VIJAY
A14: Name : Ishwar Chaudhari
A15: Phone : 8956752696 | B15: FT | C15: 45K | D15: KAMINI
A16: Name : Ranjan
A17: Phone : 7978184161 | B17: NPC | D17: AMIT
A18: Name : RK Venkatesh
A19: Phone : 8463959107 | B19: CD | D19: KAMINI
A20: Name : Nawaz
A21: Phone : 8864036651 | B21: NC | D21: VIJAY
A22: Name : Shanmugasunderam
A23: Phone : 9884876096 | B23: CB | D23: VIKASH
A24: Name : Rajeshvijayan m
A25: Phone : 9840220404 | B25: NI | D25: SHIVANI
A26: Name : Jaydeep
A27: Phone : 7030131383 | B27: FOLLOW UP | D27: VOM
A28: Name : Phamdom Prince Singh
A29: Phone : 9910396513 | B29: BUSY | D29: RITU
A30: Name : Boopathi
A31: Phone : 6380239291 | B31: NI | D31: VIKASH
A32: Name : TEJAS SHASTRI
A33: Phone : 9986813658 | B33: BUSY | D33: KAMINI
A34: Name : Guna
A35: Phone : 9066066096 | B35: NI | D35: AMIT
A36: Name : Udayakumar
A37: Phone : 8903386001 | B37: NI | D37: VIKASH
A38: Name : bharti
A39: Phone : 9600399985 | B39: CD | D39: VIKASH
A40: Name : Mohd samim
...

Sheet 21-10-24
A1: CLIENTS DETAILS | B1: REMARK | C1: INVESTMENT | D1: EMP…
A2: Name : sabyasachi barik | H2: TOTAL LEADS - 112
A3: Phone : 9668688811 | B3: NPC | D3: KAMINI | H3: Date -21.10.24
A4: Name : Roy | H4: FT | I4: 8
A5: Phone : 8262038635 | B5: NI | D5: VOM | H5: INTERESTED | I5: 1
A6: Name : Bhupendra Meher | H6: FOLLOWUP | I6: 5
A7: Phone : 8446487990 | B7: NI | D7: RISHI | H7: CB | I7: 9
A8: Name : Krishuu | H8: BUSY | I8: 8
A9: Phone : 7057323657 | B9: NI | D9: AMIT | H9: CD | I9: 6
A10: Name : Vamsi | H10: NI | I10: 21
A11: Phone : 9753041979 | B11: SF | D11: VISHNU | H11: NPC | I11: 35
A12: Name : Rajat panigrahy | H12: OTHERS | I12: 20
A13: Phone : 9438293909 | B13: BUSY | D13: RITU
A14: Name : Sunakar Rout
A15: Phone : 9861106424 | B15: FUND ISSUE | D15: AYUSH
A16: Name : Dilip Desai
A17: Phone : 7710928635 | B17: INTERESTED | D17: RAJ
A18: Name : Liju
A19: Phone : 9072792516 | B19: NI | D19: RAJ
A20: Name : Dhanesh chikhale
A21: Phone : 8208804996 | B21: CB | D21: VINAY
A22: Name : Ra i
A23: Phone : 7090583628 | B23: NPC | D23: JITENDRA
A24: Name : Spp
A25: Phone : 8118059130 | B25: NI | C25: ` | D25: SHIVANI
A26: Name : Ganesh hambir
A27: Phone : 9702104757 | B27: NI | D27: VIJAY
A28: Name : Raviraj Chopdar
A29: Phone : 7447692443 | B29: NI | C29: AFTER MARKET | D29: KAMINI
A30: Name : Harshithaa. M
A31: Phone : 6362958657 | B31: NPC | D31: AMBRISH
A32: Name : Patakamuri
A33: Phone : 9545015356 | B33: NPC | D33: RISHI
A34: Name : NITIN JAIN
A35: Phone : 9810371278 | B35: NI | D35: VISHNU
A36: Name : Lakshminarayana
A37: Phone : 9343735842 | B37: NC | D37: KAMINI
A38: Name : APIUTH
A39: Phone : 9884582101 | B39: NI | D39: RAJ
A40: Name : R Muthukumar
...

Sheet Sheet1
A1: TOTAL LEADS -
A2: Date -
A3: FT
A4: INTERESTED
A5: FOLLOWUP
A6: CB
A7: BUSY
A8: CD
A9: NI
A10: NPC
A11: OTHERS

Sheet Sheet7
A1: TOTAL LEADS -
A2: Date -
A3: FT
A4: INTERESTED
A5: FOLLOWUP
A6: CB
A7: BUSY
A8: CD
A9: NI
A10: NPC
A11: OTHERS

Sheet 22-10-2024
A1: CLIENTS DETAILS | B1: REMARK | C1: INVESTMENT | D1: EMP… | G1: TOTAL LEADS - 43
A2: Name : Sohan K | G2: Date -22.10.24
A3: Phone : 8767192253 | B3: PAYMENT DONE | D3: KAMINI | G3: FT | H3: 4
A4: Name : Rohittttttttttt | G4: INTERESTED | H4: 3
A5: Phone : 9968114181 | B5: SF | D5: RAJ | G5: FOLLOWUP | H5: 3
A6: Name : MANOJ BASUTKAR | G6: CB | H6: 5
A7: Phone : 9930161763 | B7: BUSY | C7: REPEAT NO…. | D7: AMIT | G7: BUSY | H7: 2
A8: Name : Ruksar | G8: CD | H8: 1
A9: Phone : 9967894851 | B9: NPC | D9: VISHNU | G9: NI | H9: 1
A10: Name : RAMALLA JOSEPH | G10: NPC | H10: 10
A11: Phone : 9182230137 | B11: LI | D11: AYUSH | G11: OTHERS | H11: 13
A12: Name : Joseph
A13: Phone : 9182230127 | B13: WRONG NO….. | D13: VOM
A14: Name : SHAIKH Ali
A15: Phone : 8010836792 | B15: CAPITAL ISSUE | D15: VOM
A16: Name : Deborshe Dutta
A17: Phone : 6370416011 | B17: DETAIL SEND | D17: RISHI
A18: Name : Amol Raut | B18: FT
A19: Phone : 9021986751 | B19: FT | C19: 50K LOSS ,7K | D19: KAMINI
A20: Name : Shaikh hunain
A21: Phone : 9175747938 | B21: NI | D21: VOM
A22: Name : Janesh
A23: Phone : 8169098400 | B23: PAYMENT DONE | D23: KAMINI
A24: Name : Swati
A25: Phone : 7709848649 | B25: FT | D25: RANJANA | F25: 45931
A26: Name : Telepu lanja
A27: Phone : 8712326390 | B27: LI | D27: AMIT
A28: Name : Sundar n
A29: Phone : 8610974253 | B29: CD | C29: REPEAT NO…. | D29: KAMINI
A30: Name : Eru halyapnor
A31: Phone : 8668490175 | B31: NI | D31: VISHNU
A32: Name : Mahesh Mhatre
A33: Phone : 9975033909 | B33: CB | D33: AMAR
A34: Name : Sanjay Bora
A35: Phone : 9322267596 | B35: NI | D35: SHIVANI
A36: Name : Omappa
A37: Phone : 9731408234 | B37: NI | D37: VOM
A38: Name : Irfan Maner
A39: Phone : 8237621054 | B39: FOLLOW UP | C39: 5K | D39: AMIT
A40: Name : Mohanlal
...

Sheet 23-10-24
A1: CLIENTS DETAILS | B1: REMARK | C1: INVESTMENT | D1: EMP…
A2: Name : Kathiravan | F2: TOTAL LEADS - 50
A3: Phone : 9626618105 | B3: NI | D3: KAMINI | F3: Date -23.10.24
A4: name:sunil kumar mahala | B4: FT | F4: FT | G4: 4 | H4: 2
A5: Phone : 9938515326 | B5: FT | C5: 50K | D5: MANSING | E5: 28/12/2024 | F5: INTERESTED | G5: 7
A6: Name : Nagarathinam | F6: FOLLOWUP | G6: 5 | H6: 1
A7: Phone : 9840301101 | B7: NPC | D7: VOM | F7: CB | G7: 4
A8: Name : Vidya | F8: BUSY | G8: 2
A9: Phone : 9900378642 | B9: PAYMENT DONE | D9: ABHAY | F9: CD | G9: 2
A10: Name : Pranav | F10: NI | G10: 6
A11: Phone : 7757006362 | B11: NI | D11: VIKASH | F11: NPC | G11: 13
A12: Name : Pradeep kumar | F12: OTHERS | G12: 7
A13: Phone : 8490032346 | B13: CB 4PM | D13: RISHI
A14: Name : Juned
A15: Phone : 9284157540 | B15: INTERESTED | D15: MAHENDRA
A16: Name : Kalyan Karande
A17: Phone : 7263956744 | B17: CD | D17: VISHNU
A18: Name : Debajyoti
A19: Phone : 9632248586 | B19: PAYMENT DONE | D19: VOM
A20: Name : Swati
A21: Phone : 7709848649 | B21: FOLLOW UP | D21: VOM
A22: Name : M srinibas Rao
A23: Phone : 9437305754 | B23: FOLLOW UP | C23: REPEAT | D23: AYUSH
A24: Name : Keerthi vasan
A25: Phone : 6369695012 | B25: CD | D25: RAJ
A26: Name : Abh
A27: Phone : 9172515944 | B27: INTERESTED | D27: MAHENDRA
A28: Name : Sweety Chauhan
A29: Phone : 8999789611 | B29: FUND ISSUE | C29: 6K | D29: RAJ
A30: Name : Shiv
A31: Phone : 9899883414 | B31: INTERESTED | D31: JITENDRA
A32: Name : Chandrahasa
A33: Phone : 9480116680 | B33: CAPITAL ISSUE | D33: VIKASH
A34: Name : Manikandan | B34: FT
A35: Phone : 9841338829 | B35: FT | C35: 30K-40K | D35: AYUSH
A36: Name : S M BIRADAR
A37: Phone : 9740625189 | B37: INTERESTED | C37: DETAIL SEND | D37: VIKASH
A38: Name : Tushar kadam
A39: Phone : 8779839655 | B39: NC | D39: RAJ
A40: Name : Babu c
...

Sheet 24-10-24
A1: CLIENTS DETAILS | B1: REMARK | C1: INVESTMENT | D1: EMP…
A2: Name : I am sakaham | G2: TOTAL LEADS -52
A3: Phone : 7821055529 | B3: SF | D3: AMIT | G3: Date -24.10.24
A4: Name : Bagtavar | G4: FT | H4: 7
A5: Phone : 9145615006 | B5: CD | D5: KAMINI | G5: INTERESTED | H5: 4
A6: Name : Vinod sultane | G6: FOLLOWUP | H6: 6
A7: Phone : 9604020588 | B7: 2K CAPITAL | D7: RITU | G7: CB | H7: 0
A8: Name : Depu | G8: BUSY | H8: 2
A9: Phone : 9028553001 | B9: INVALID | D9: RAJ | G9: CD | H9: 6 | L9: 36
A10: Name : Naresh | G10: NI | H10: 6 | L10: =49-39 -> 10
A11: Phone : 9060465599 | B11: NPC | D11: MAHENDRA | G11: NPC | H11: 9
A12: Name : Ritesh patil | G12: OTHERS | H12: 10
A13: Phone : 9272105354 | B13: BLOCK | D13: VIKASH
A14: Name : K suganya
A15: Phone : 7550055114 | B15: LI | D15: RISHI
A16: Name : laxman rathod
A17: Phone : 7721025407 | B17: NI | D17: VIKASH
A18: Name : Billal
A19: Phone : 8939807890 | B19: BUSY | D19: AMIT
A20: Name : Manju reddy
